Workbook

Sheet Summary
A1: Hours summary by resource
A2: All figures are formulas: tasks roll up to activities, activities roll up here.
A4: Hours by role and phase
A5: Code | B5: Role | C5: Phase 1 | D5: Phase 2 | E5: Phase 3 | F5: Phase 4 | G5: Total hours | H5: Person-weeks
A6: PM | B6: Program / Project Manager | C6: =SUMPRODUCT(('Activity Hours'!$C$5:$C$87=C$5)*INDEX('Activity Hours'!$I$5:$T$87,0,MATCH($A6,'Activity Hours'!$I$4:$T$4,0))) -> 454 | D6: =SUMPRODUCT(('Activity Hours'!$C$5:$C$87=D$5)*INDEX('Activity Hours'!$I$5:$T$87,0,MATCH($A6,'Activity Hours'!$I$4:$T$4,0))) -> 434 | E6: =SUMPRODUCT(('Activity Hours'!$C$5:$C$87=E$5)*INDEX('Activity Hours'!$I$5:$T$87,0,MATCH($A6,'Activity Hours'!$I$4:$T$4,0))) -> 444 | F6: =SUMPRODUCT(('Activity Hours'!$C$5:$C$87=F$5)*INDEX('Activity Hours'!$I$5:$T$87,0,MATCH($A6,'Activity Hours'!$I$4:$T$4,0))) -> 402 | G6: =SUM(C6:F6) -> 1734 | H6: =IF(Resources!$B$3>0,G6/Resources!$B$3,0) -> 43.35
A7: CA | B7: Cloud / Platform Architect | C7: =SUMPRODUCT(('Activity Hours'!$C$5:$C$87=C$5)*INDEX('Activity Hours'!$I$5:$T$87,0,MATCH($A7,'Activity Hours'!$I$4:$T$4,0))) -> 306 | D7: =SUMPRODUCT(('Activity Hours'!$C$5:$C$87=D$5)*INDEX('Activity Hours'!$I$5:$T$87,0,MATCH($A7,'Activity Hours'!$I$4:$T$4,0))) -> 48 | E7: =SUMPRODUCT(('Activity Hours'!$C$5:$C$87=E$5)*INDEX('Activity Hours'!$I$5:$T$87,0,MATCH($A7,'Activity Hours'!$I$4:$T$4,0))) -> 153 | F7: =SUMPRODUCT(('Activity Hours'!$C$5:$C$87=F$5)*INDEX('Activity Hours'!$I$5:$T$87,0,MATCH($A7,'Activity Hours'!$I$4:$T$4,0))) -> 185 | G7: =SUM(C7:F7) -> 692 | H7: =IF(Resources!$B$3>0,G7/Resources!$B$3,0) -> 17.3
A8: DO | B8: Platform / DevOps Engineer | C8: =SUMPRODUCT(('Activity Hours'!$C$5:$C$87=C$5)*INDEX('Activity Hours'!$I$5:$T$87,0,MATCH($A8,'Activity Hours'!$I$4:$T$4,0))) -> 917 | D8: =SUMPRODUCT(('Activity Hours'!$C$5:$C$87=D$5)*INDEX('Activity Hours'!$I$5:$T$87,0,MATCH($A8,'Activity Hours'!$I$4:$T$4,0))) -> 334 | E8: =SUMPRODUCT(('Activity Hours'!$C$5:$C$87=E$5)*INDEX('Activity Hours'!$I$5:$T$87,0,MATCH($A8,'Activity Hours'!$I$4:$T$4,0))) -> 581 | F8: =SUMPRODUCT(('Activity Hours'!$C$5:$C$87=F$5)*INDEX('Activity Hours'!$I$5:$T$87,0,MATCH($A8,'Activity Hours'!$I$4:$T$4,0))) -> 817 | G8: =SUM(C8:F8) -> 2649 | H8: =IF(Resources!$B$3>0,G8/Resources!$B$3,0) -> 66.225
A9: SE | B9: Security Engineer | C9: =SUMPRODUCT(('Activity Hours'!$C$5:$C$87=C$5)*INDEX('Activity Hours'!$I$5:$T$87,0,MATCH($A9,'Activity Hours'!$I$4:$T$4,0))) -> 414 | D9: =SUMPRODUCT(('Activity Hours'!$C$5:$C$87=D$5)*INDEX('Activity Hours'!$I$5:$T$87,0,MATCH($A9,'Activity Hours'!$I$4:$T$4,0))) -> 96 | E9: =SUMPRODUCT(('Activity Hours'!$C$5:$C$87=E$5)*INDEX('Activity Hours'!$I$5:$T$87,0,MATCH($A9,'Activity Hours'!$I$4:$T$4,0))) -> 273 | F9: =SUMPRODUCT(('Activity Hours'!$C$5:$C$87=F$5)*INDEX('Activity Hours'!$I$5:$T$87,0,MATCH($A9,'Activity Hours'!$I$4:$T$4,0))) -> 244 | G9: =SUM(C9:F9) -> 1027 | H9: =IF(Resources!$B$3>0,G9/Resources!$B$3,0) -> 25.675
A10: AIA | B10: AI Architect | C10: =SUMPRODUCT(('Activity Hours'!$C$5:$C$87=C$5)*INDEX('Activity Hours'!$I$5:$T$87,0,MATCH($A10,'Activity Hours'!$I$4:$T$4,0))) -> 131 | D10: =SUMPRODUCT(('Activity Hours'!$C$5:$C$87=D$5)*INDEX('Activity Hours'!$I$5:$T$87,0,MATCH($A10,'Activity Hours'!$I$4:$T$4,0))) -> 511 | E10: =SUMPRODUCT(('Activity Hours'!$C$5:$C$87=E$5)*INDEX('Activity Hours'!$I$5:$T$87,0,MATCH($A10,'Activity Hours'!$I$4:$T$4,0))) -> 521 | F10: =SUMPRODUCT(('Activity Hours'!$C$5:$C$87=F$5)*INDEX('Activity Hours'!$I$5:$T$87,0,MATCH($A10,'Activity Hours'!$I$4:$T$4,0))) -> 195 | G10: =SUM(C10:F10) -> 1358 | H10: =IF(Resources!$B$3>0,G10/Resources!$B$3,0) -> 33.95
A11: AIE | B11: AI / ML Engineer | C11: =SUMPRODUCT(('Activity Hours'!$C$5:$C$87=C$5)*INDEX('Activity Hours'!$I$5:$T$87,0,MATCH($A11,'Activity Hours'!$I$4:$T$4,0))) -> 0 | D11: =SUMPRODUCT(('Activity Hours'!$C$5:$C$87=D$5)*INDEX('Activity Hours'!$I$5:$T$87,0,MATCH($A11,'Activity Hours'!$I$4:$T$4,0))) -> 2024 | E11: =SUMPRODUCT(('Activity Hours'!$C$5:$C$87=E$5)*INDEX('Activity Hours'!$I$5:$T$87,0,MATCH($A11,'Activity Hours'!$I$4:$T$4,0))) -> 2581 | F11: =SUMPRODUCT(('Activity Hours'!$C$5:$C$87=F$5)*INDEX('Activity Hours'!$I$5:$T$87,0,MATCH($A11,'Activity Hours'!$I$4:$T$4,0))) -> 1143 | G11: =SUM(C11:F11) -> 5748 | H11: =IF(Resources!$B$3>0,G11/Resources!$B$3,0) -> 143.7
A12: DE | B12: Data Engineer | C12: =SUMPRODUCT(('Activity Hours'!$C$5:$C$87=C$5)*INDEX('Activity Hours'!$I$5:$T$87,0,MATCH($A12,'Activity Hours'!$I$4:$T$4,0))) -> 162 | D12: =SUMPRODUCT(('Activity Hours'!$C$5:$C$87=D$5)*INDEX('Activity Hours'!$I$5:$T$87,0,MATCH($A12,'Activity Hours'!$I$4:$T$4,0))) -> 1227 | E12: =SUMPRODUCT(('Activity Hours'!$C$5:$C$87=E$5)*INDEX('Activity Hours'!$I$5:$T$87,0,MATCH($A12,'Activity Hours'!$I$4:$T$4,0))) -> 885 | F12: =SUMPRODUCT(('Activity Hours'!$C$5:$C$87=F$5)*INDEX('Activity Hours'!$I$5:$T$87,0,MATCH($A12,'Activity Hours'!$I$4:$T$4,0))) -> 661 | G12: =SUM(C12:F12) -> 2935 | H12: =IF(Resources!$B$3>0,G12/Resources!$B$3,0) -> 73.375
A13: DG | B13: Data Architect / Governance | C13: =SUMPRODUCT(('Activity Hours'!$C$5:$C$87=C$5)*INDEX('Activity Hours'!$I$5:$T$87,0,MATCH($A13,'Activity Hours'!$I$4:$T$4,0))) -> 346 | D13: =SUMPRODUCT(('Activity Hours'!$C$5:$C$87=D$5)*INDEX('Activity Hours'!$I$5:$T$87,0,MATCH($A13,'Activity Hours'!$I$4:$T$4,0))) -> 170 | E13: =SUMPRODUCT(('Activity Hours'!$C$5:$C$87=E$5)*INDEX('Activity Hours'!$I$5:$T$87,0,MATCH($A13,'Activity Hours'!$I$4:$T$4,0))) -> 37 | F13: =SUMPRODUCT(('Activity Hours'!$C$5:$C$87=F$5)*INDEX('Activity Hours'!$I$5:$T$87,0,MATCH($A13,'Activity Hours'!$I$4:$T$4,0))) -> 201 | G13: =SUM(C13:F13) -> 754 | H13: =IF(Resources!$B$3>0,G13/Resources!$B$3,0) -> 18.85
A14: DEV | B14: Full-stack Developer | C14: =SUMPRODUCT(('Activity Hours'!$C$5:$C$87=C$5)*INDEX('Activity Hours'!$I$5:$T$87,0,MATCH($A14,'Activity Hours'!$I$4:$T$4,0))) -> 0 | D14: =SUMPRODUCT(('Activity Hours'!$C$5:$C$87=D$5)*INDEX('Activity Hours'!$I$5:$T$87,0,MATCH($A14,'Activity Hours'!$I$4:$T$4,0))) -> 319 | E14: =SUMPRODUCT(('Activity Hours'!$C$5:$C$87=E$5)*INDEX('Activity Hours'!$I$5:$T$87,0,MATCH($A14,'Activity Hours'!$I$4:$T$4,0))) -> 1306 | F14: =SUMPRODUCT(('Activity Hours'!$C$5:$C$87=F$5)*INDEX('Activity Hours'!$I$5:$T$87,0,MATCH($A14,'Activity Hours'!$I$4:$T$4,0))) -> 406 | G14: =SUM(C14:F14) -> 2031 | H14: =IF(Resources!$B$3>0,G14/Resources!$B$3,0) -> 50.775
A15: BA | B15: Business Analyst / Product Owner | C15: =SUMPRODUCT(('Activity Hours'!$C$5:$C$87=C$5)*INDEX('Activity Hours'!$I$5:$T$87,0,MATCH($A15,'Activity Hours'!$I$4:$T$4,0))) -> 491 | D15: =SUMPRODUCT(('Activity Hours'!$C$5:$C$87=D$5)*INDEX('Activity Hours'!$I$5:$T$87,0,MATCH($A15,'Activity Hours'!$I$4:$T$4,0))) -> 493 | E15: =SUMPRODUCT(('Activity Hours'!$C$5:$C$87=E$5)*INDEX('Activity Hours'!$I$5:$T$87,0,MATCH($A15,'Activity Hours'!$I$4:$T$4,0))) -> 795 | F15: =SUMPRODUCT(('Activity Hours'!$C$5:$C$87=F$5)*INDEX('Activity Hours'!$I$5:$T$87,0,MATCH($A15,'Activity Hours'!$I$4:$T$4,0))) -> 446 | G15: =SUM(C15:F15) -> 2225 | H15: =IF(Resources!$B$3>0,G15/Resources!$B$3,0) -> 55.625
A16: QA | B16: QA / Test Engineer | C16: =SUMPRODUCT(('Activity Hours'!$C$5:$C$87=C$5)*INDEX('Activity Hours'!$I$5:$T$87,0,MATCH($A16,'Activity Hours'!$I$4:$T$4,0))) -> 76 | D16: =SUMPRODUCT(('Activity Hours'!$C$5:$C$87=D$5)*INDEX('Activity Hours'!$I$5:$T$87,0,MATCH($A16,'Activity Hours'!$I$4:$T$4,0))) -> 712 | E16: =SUMPRODUCT(('Activity Hours'!$C$5:$C$87=E$5)*INDEX('Activity Hours'!$I$5:$T$87,0,MATCH($A16,'Activity Hours'!$I$4:$T$4,0))) -> 983 | F16: =SUMPRODUCT(('Activity Hours'!$C$5:$C$87=F$5)*INDEX('Activity Hours'!$I$5:$T$87,0,MATCH($A16,'Activity Hours'!$I$4:$T$4,0))) -> 488 | G16: =SUM(C16:F16) -> 2259 | H16: =IF(Resources!$B$3>0,G16/Resources!$B$3,0) -> 56.475
A17: CM | B17: Change & Training Lead | C17: =SUMPRODUCT(('Activity Hours'!$C$5:$C$87=C$5)*INDEX('Activity Hours'!$I$5:$T$87,0,MATCH($A17,'Activity Hours'!$I$4:$T$4,0))) -> 16 | D17: =SUMPRODUCT(('Activity Hours'!$C$5:$C$87=D$5)*INDEX('Activity Hours'!$I$5:$T$87,0,MATCH($A17,'Activity Hours'!$I$4:$T$4,0))) -> 97 | E17: =SUMPRODUCT(('Activity Hours'!$C$5:$C$87=E$5)*INDEX('Activity Hours'!$I$5:$T$87,0,MATCH($A17,'Activity Hours'!$I$4:$T$4,0))) -> 222 | F17: =SUMPRODUCT(('Activity Hours'!$C$5:$C$87=F$5)*INDEX('Activity Hours'!$I$5:$T$87,0,MATCH($A17,'Activity Hours'!$I$4:$T$4,0))) -> 253 | G17: =SUM(C17:F17) -> 588 | H17: =IF(Resources!$B$3>0,G17/Resources!$B$3,0) -> 14.7
B18: Total | C18: =SUM(C6:C17) -> 3313 | D18: =SUM(D6:D17) -> 6465 | E18: =SUM(E6:E17) -> 8781 | F18: =SUM(F6:F17) -> 5441 | G18: =SUM(G6:G17) -> 24000 | H18: =SUM(H6:H17) -> 600
A21: Hours by role and track
A22: Code | B22: Role | C22: AI Platform Setup | D22: AI Data Readiness | E22: AI Use Cases | F22: Program Management | G22: Total hours
A23: PM | B23: Program / Project Manager | C23: =SUMPRODUCT(('Activity Hours'!$B$5:$B$87=C$22)*INDEX('Activity Hours'!$I$5:$T$87,0,MATCH($A23,'Activity Hours'!$I$4:$T$4,0))) -> 8 | D23: =SUMPRODUCT(('Activity Hours'!$B$5:$B$87=D$22)*INDEX('Activity Hours'!$I$5:$T$87,0,MATCH($A23,'Activity Hours'!$I$4:$T$4,0))) -> 16 | E23: =SUMPRODUCT(('Activity Hours'!$B$5:$B$87=E$22)*INDEX('Activity Hours'!$I$5:$T$87,0,MATCH($A23,'Activity Hours'!$I$4:$T$4,0))) -> 246 | F23: =SUMPRODUCT(('Activity Hours'!$B$5:$B$87=F$22)*INDEX('Activity Hours'!$I$5:$T$87,0,MATCH($A23,'Activity Hours'!$I$4:$T$4,0))) -> 1464 | G23: =SUM(C23:F23) -> 1734
A24: CA | B24: Cloud / Platform Architect | C24: =SUMPRODUCT(('Activity Hours'!$B$5:$B$87=C$22)*INDEX('Activity Hours'!$I$5:$T$87,0,MATCH($A24,'Activity Hours'!$I$4:$T$4,0))) -> 467 | D24: =SUMPRODUCT(('Activity Hours'!$B$5:$B$87=D$22)*INDEX('Activity Hours'!$I$5:$T$87,0,MATCH($A24,'Activity Hours'!$I$4:$T$4,0))) -> 113 | E24: =SUMPRODUCT(('Activity Hours'!$B$5:$B$87=E$22)*INDEX('Activity Hours'!$I$5:$T$87,0,MATCH($A24,'Activity Hours'!$I$4:$T$4,0))) -> 16 | F24: =SUMPRODUCT(('Activity Hours'!$B$5:$B$87=F$22)*INDEX('Activity Hours'!$I$5:$T$87,0,MATCH($A24,'Activity Hours'!$I$4:$T$4,0))) -> 96 | G24: =SUM(C24:F24) -> 692
A25: DO | B25: Platform / DevOps Engineer | C25: =SUMPRODUCT(('Activity Hours'!$B$5:$B$87=C$22)*INDEX('Activity Hours'!$I$5:$T$87,0,MATCH($A25,'Activity Hours'!$I$4:$T$4,0))) -> 1917 | D25: =SUMPRODUCT(('Activity Hours'!$B$5:$B$87=D$22)*INDEX('Activity Hours'!$I$5:$T$87,0,MATCH($A25,'Activity Hours'!$I$4:$T$4,0))) -> 470 | E25: =SUMPRODUCT(('Activity Hours'!$B$5:$B$87=E$22)*INDEX('Activity Hours'!$I$5:$T$87,0,MATCH($A25,'Activity Hours'!$I$4:$T$4,0))) -> 262 | F25: =SUMPRODUCT(('Activity Hours'!$B$5:$B$87=F$22)*INDEX('Activity Hours'!$I$5:$T$87,0,MATCH($A25,'Activity Hours'!$I$4:$T$4,0))) -> 0 | G25: =SUM(C25:F25) -> 2649
A26: SE | B26: Security Engineer | C26: =SUMPRODUCT(('Activity Hours'!$B$5:$B$87=C$22)*INDEX('Activity Hours'!$I$5:$T$87,0,MATCH($A26,'Activity Hours'!$I$4:$T$4,0))) -> 641 | D26: =SUMPRODUCT(('Activity Hours'!$B$5:$B$87=D$22)*INDEX('Activity Hours'!$I$5:$T$87,0,MATCH($A26,'Activity Hours'!$I$4:$T$4,0))) -> 199 | E26: =SUMPRODUCT(('Activity Hours'!$B$5:$B$87=E$22)*INDEX('Activity Hours'!$I$5:$T$87,0,MATCH($A26,'Activity Hours'!$I$4:$T$4,0))) -> 187 | F26: =SUMPRODUCT(('Activity Hours'!$B$5:$B$87=F$22)*INDEX('Activity Hours'!$I$5:$T$87,0,MATCH($A26,'Activity Hours'!$I$4:$T$4,0))) -> 0 | G26: =SUM(C26:F26) -> 1027
A27: AIA | B27: AI Architect | C27: =SUMPRODUCT(('Activity Hours'!$B$5:$B$87=C$22)*INDEX('Activity Hours'!$I$5:$T$87,0,MATCH($A27,'Activity Hours'!$I$4:$T$4,0))) -> 499 | D27: =SUMPRODUCT(('Activity Hours'!$B$5:$B$87=D$22)*INDEX('Activity Hours'!$I$5:$T$87,0,MATCH($A27,'Activity Hours'!$I$4:$T$4,0))) -> 212 | E27: =SUMPRODUCT(('Activity Hours'!$B$5:$B$87=E$22)*INDEX('Activity Hours'!$I$5:$T$87,0,MATCH($A27,'Activity Hours'!$I$4:$T$4,0))) -> 551 | F27: =SUMPRODUCT(('Activity Hours'!$B$5:$B$87=F$22)*INDEX('Activity Hours'!$I$5:$T$87,0,MATCH($A27,'Activity Hours'!$I$4:$T$4,0))) -> 96 | G27: =SUM(C27:F27) -> 1358
A28: AIE | B28: AI / ML Engineer | C28: =SUMPRODUCT(('Activity Hours'!$B$5:$B$87=C$22)*INDEX('Activity Hours'!$I$5:$T$87,0,MATCH($A28,'Activity Hours'!$I$4:$T$4,0))) -> 1739 | D28: =SUMPRODUCT(('Activity Hours'!$B$5:$B$87=D$22)*INDEX('Activity Hours'!$I$5:$T$87,0,MATCH($A28,'Activity Hours'!$I$4:$T$4,0))) -> 1114 | E28: =SUMPRODUCT(('Activity Hours'!$B$5:$B$87=E$22)*INDEX('Activity Hours'!$I$5:$T$87,0,MATCH($A28,'Activity Hours'!$I$4:$T$4,0))) -> 2895 | F28: =SUMPRODUCT(('Activity Hours'!$B$5:$B$87=F$22)*INDEX('Activity Hours'!$I$5:$T$87,0,MATCH($A28,'Activity Hours'!$I$4:$T$4,0))) -> 0 | G28: =SUM(C28:F28) -> 5748
A29: DE | B29: Data Engineer | C29: =SUMPRODUCT(('Activity Hours'!$B$5:$B$87=C$22)*INDEX('Activity Hours'!$I$5:$T$87,0,MATCH($A29,'Activity Hours'!$I$4:$T$4,0))) -> 93 | D29: =SUMPRODUCT(('Activity Hours'!$B$5:$B$87=D$22)*INDEX('Activity Hours'!$I$5:$T$87,0,MATCH($A29,'Activity Hours'!$I$4:$T$4,0))) -> 2071 | E29: =SUMPRODUCT(('Activity Hours'!$B$5:$B$87=E$22)*INDEX('Activity Hours'!$I$5:$T$87,0,MATCH($A29,'Activity Hours'!$I$4:$T$4,0))) -> 771 | F29: =SUMPRODUCT(('Activity Hours'!$B$5:$B$87=F$22)*INDEX('Activity Hours'!$I$5:$T$87,0,MATCH($A29,'Activity Hours'!$I$4:$T$4,0))) -> 0 | G29: =SUM(C29:F29) -> 2935
A30: DG | B30: Data Architect / Governance | C30: =SUMPRODUCT(('Activity Hours'!$B$5:$B$87=C$22)*INDEX('Activity Hours'!$I$5:$T$87,0,MATCH($A30,'Activity Hours'!$I$4:$T$4,0))) -> 0 | D30: =SUMPRODUCT(('Activity Hours'!$B$5:$B$87=D$22)*INDEX('Activity Hours'!$I$5:$T$87,0,MATCH($A30,'Activity Hours'!$I$4:$T$4,0))) -> 738 | E30: =SUMPRODUCT(('Activity Hours'!$B$5:$B$87=E$22)*INDEX('Activity Hours'!$I$5:$T$87,0,MATCH($A30,'Activity Hours'!$I$4:$T$4,0))) -> 16 | F30: =SUMPRODUCT(('Activity Hours'!$B$5:$B$87=F$22)*INDEX('Activity Hours'!$I$5:$T$87,0,MATCH($A30,'Activity Hours'!$I$4:$T$4,0))) -> 0 | G30: =SUM(C30:F30) -> 754
A31: DEV | B31: Full-stack Developer | C31: =SUMPRODUCT(('Activity Hours'!$B$5:$B$87=C$22)*INDEX('Activity Hours'!$I$5:$T$87,0,MATCH($A31,'Activity Hours'!$I$4:$T$4,0))) -> 732 | D31: =SUMPRODUCT(('Activity Hours'!$B$5:$B$87=D$22)*INDEX('Activity Hours'!$I$5:$T$87,0,MATCH($A31,'Activity Hours'!$I$4:$T$4,0))) -> 0 | E31: =SUMPRODUCT(('Activity Hours'!$B$5:$B$87=E$22)*INDEX('Activity Hours'!$I$5:$T$87,0,MATCH($A31,'Activity Hours'!$I$4:$T$4,0))) -> 1299 | F31: =SUMPRODUCT(('Activity Hours'!$B$5:$B$87=F$22)*INDEX('Activity Hours'!$I$5:$T$87,0,MATCH($A31,'Activity Hours'!$I$4:$T$4,0))) -> 0 | G31: =SUM(C31:F31) -> 2031
A32: BA | B32: Business Analyst / Product Owner | C32: =SUMPRODUCT(('Activity Hours'!$B$5:$B$87=C$22)*INDEX('Activity Hours'!$I$5:$T$87,0,MATCH($A32,'Activity Hours'!$I$4:$T$4,0))) -> 174 | D32: =SUMPRODUCT(('Activity Hours'!$B$5:$B$87=D$22)*INDEX('Activity Hours'!$I$5:$T$87,0,MATCH($A32,'Activity Hours'!$I$4:$T$4,0))) -> 510 | E32: =SUMPRODUCT(('Activity Hours'!$B$5:$B$87=E$22)*INDEX('Activity Hours'!$I$5:$T$87,0,MATCH($A32,'Activity Hours'!$I$4:$T$4,0))) -> 1541 | F32: =SUMPRODUCT(('Activity Hours'!$B$5:$B$87=F$22)*INDEX('Activity Hours'!$I$5:$T$87,0,MATCH($A32,'Activity Hours'!$I$4:$T$4,0))) -> 0 | G32: =SUM(C32:F32) -> 2225
A33: QA | B33: QA / Test Engineer | C33: =SUMPRODUCT(('Activity Hours'!$B$5:$B$87=C$22)*INDEX('Activity Hours'!$I$5:$T$87,0,MATCH($A33,'Activity Hours'!$I$4:$T$4,0))) -> 739 | D33: =SUMPRODUCT(('Activity Hours'!$B$5:$B$87=D$22)*INDEX('Activity Hours'!$I$5:$T$87,0,MATCH($A33,'Activity Hours'!$I$4:$T$4,0))) -> 505 | E33: =SUMPRODUCT(('Activity Hours'!$B$5:$B$87=E$22)*INDEX('Activity Hours'!$I$5:$T$87,0,MATCH($A33,'Activity Hours'!$I$4:$T$4,0))) -> 1015 | F33: =SUMPRODUCT(('Activity Hours'!$B$5:$B$87=F$22)*INDEX('Activity Hours'!$I$5:$T$87,0,MATCH($A33,'Activity Hours'!$I$4:$T$4,0))) -> 0 | G33: =SUM(C33:F33) -> 2259
A34: CM | B34: Change & Training Lead | C34: =SUMPRODUCT(('Activity Hours'!$B$5:$B$87=C$22)*INDEX('Activity Hours'!$I$5:$T$87,0,MATCH($A34,'Activity Hours'!$I$4:$T$4,0))) -> 8 | D34: =SUMPRODUCT(('Activity Hours'!$B$5:$B$87=D$22)*INDEX('Activity Hours'!$I$5:$T$87,0,MATCH($A34,'Activity Hours'!$I$4:$T$4,0))) -> 114 | E34: =SUMPRODUCT(('Activity Hours'!$B$5:$B$87=E$22)*INDEX('Activity Hours'!$I$5:$T$87,0,MATCH($A34,'Activity Hours'!$I$4:$T$4,0))) -> 466 | F34: =SUMPRODUCT(('Activity Hours'!$B$5:$B$87=F$22)*INDEX('Activity Hours'!$I$5:$T$87,0,MATCH($A34,'Activity Hours'!$I$4:$T$4,0))) -> 0 | G34: =SUM(C34:F34) -> 588
B35: Total | C35: =SUM(C23:C34) -> 7017 | D35: =SUM(D23:D34) -> 6062 | E35: =SUM(E23:E34) -> 9265 | F35: =SUM(F23:F34) -> 1656 | G35: =SUM(G23:G34) -> 24000
A38: Hours by role and owner team
A39: Code | B39: Role | C39: Platform Engineering | D39: Foundry | E39: AI Data Lake | F39: Factory | G39: All teams | H39: Total hours
A40: PM | B40: Program / Project Manager | C40: =SUMPRODUCT(('Activity Hours'!$F$5:$F$87=C$39)*INDEX('Activity Hours'!$I$5:$T$87,0,MATCH($A40,'Activity Hours'!$I$4:$T$4,0))) -> 8 | D40: =SUMPRODUCT(('Activity Hours'!$F$5:$F$87=D$39)*INDEX('Activity Hours'!$I$5:$T$87,0,MATCH($A40,'Activity Hours'!$I$4:$T$4,0))) -> 0 | E40: =SUMPRODUCT(('Activity Hours'!$F$5:$F$87=E$39)*INDEX('Activity Hours'!$I$5:$T$87,0,MATCH($A40,'Activity Hours'!$I$4:$T$4,0))) -> 16 | F40: =SUMPRODUCT(('Activity Hours'!$F$5:$F$87=F$39)*INDEX('Activity Hours'!$I$5:$T$87,0,MATCH($A40,'Activity Hours'!$I$4:$T$4,0))) -> 246 | G40: =SUMPRODUCT(('Activity Hours'!$F$5:$F$87=G$39)*INDEX('Activity Hours'!$I$5:$T$87,0,MATCH($A40,'Activity Hours'!$I$4:$T$4,0))) -> 1464 | H40: =SUM(C40:G40) -> 1734
A41: CA | B41: Cloud / Platform Architect | C41: =SUMPRODUCT(('Activity Hours'!$F$5:$F$87=C$39)*INDEX('Activity Hours'!$I$5:$T$87,0,MATCH($A41,'Activity Hours'!$I$4:$T$4,0))) -> 543 | D41: =SUMPRODUCT(('Activity Hours'!$F$5:$F$87=D$39)*INDEX('Activity Hours'!$I$5:$T$87,0,MATCH($A41,'Activity Hours'!$I$4:$T$4,0))) -> 0 | E41: =SUMPRODUCT(('Activity Hours'!$F$5:$F$87=E$39)*INDEX('Activity Hours'!$I$5:$T$87,0,MATCH($A41,'Activity Hours'!$I$4:$T$4,0))) -> 53 | F41: =SUMPRODUCT(('Activity Hours'!$F$5:$F$87=F$39)*INDEX('Activity Hours'!$I$5:$T$87,0,MATCH($A41,'Activity Hours'!$I$4:$T$4,0))) -> 0 | G41: =SUMPRODUCT(('Activity Hours'!$F$5:$F$87=G$39)*INDEX('Activity Hours'!$I$5:$T$87,0,MATCH($A41,'Activity Hours'!$I$4:$T$4,0))) -> 96 | H41: =SUM(C41:G41) -> 692
A42: DO | B42: Platform / DevOps Engineer | C42: =SUMPRODUCT(('Activity Hours'!$F$5:$F$87=C$39)*INDEX('Activity Hours'!$I$5:$T$87,0,MATCH($A42,'Activity Hours'!$I$4:$T$4,0))) -> 1878 | D42: =SUMPRODUCT(('Activity Hours'!$F$5:$F$87=D$39)*INDEX('Activity Hours'!$I$5:$T$87,0,MATCH($A42,'Activity Hours'!$I$4:$T$4,0))) -> 358 | E42: =SUMPRODUCT(('Activity Hours'!$F$5:$F$87=E$39)*INDEX('Activity Hours'!$I$5:$T$87,0,MATCH($A42,'Activity Hours'!$I$4:$T$4,0))) -> 224 | F42: =SUMPRODUCT(('Activity Hours'!$F$5:$F$87=F$39)*INDEX('Activity Hours'!$I$5:$T$87,0,MATCH($A42,'Activity Hours'!$I$4:$T$4,0))) -> 189 | G42: =SUMPRODUCT(('Activity Hours'!$F$5:$F$87=G$39)*INDEX('Activity Hours'!$I$5:$T$87,0,MATCH($A42,'Activity Hours'!$I$4:$T$4,0))) -> 0 | H42: =SUM(C42:G42) -> 2649
A43: SE | B43: Security Engineer | C43: =SUMPRODUCT(('Activity Hours'!$F$5:$F$87=C$39)*INDEX('Activity Hours'!$I$5:$T$87,0,MATCH($A43,'Activity Hours'!$I$4:$T$4,0))) -> 688 | D43: =SUMPRODUCT(('Activity Hours'!$F$5:$F$87=D$39)*INDEX('Activity Hours'!$I$5:$T$87,0,MATCH($A43,'Activity Hours'!$I$4:$T$4,0))) -> 153 | E43: =SUMPRODUCT(('Activity Hours'!$F$5:$F$87=E$39)*INDEX('Activity Hours'!$I$5:$T$87,0,MATCH($A43,'Activity Hours'!$I$4:$T$4,0))) -> 76 | F43: =SUMPRODUCT(('Activity Hours'!$F$5:$F$87=F$39)*INDEX('Activity Hours'!$I$5:$T$87,0,MATCH($A43,'Activity Hours'!$I$4:$T$4,0))) -> 110 | G43: =SUMPRODUCT(('Activity Hours'!$F$5:$F$87=G$39)*INDEX('Activity Hours'!$I$5:$T$87,0,MATCH($A43,'Activity Hours'!$I$4:$T$4,0))) -> 0 | H43: =SUM(C43:G43) -> 1027
A44: AIA | B44: AI Architect | C44: =SUMPRODUCT(('Activity Hours'!$F$5:$F$87=C$39)*INDEX('Activity Hours'!$I$5:$T$87,0,MATCH($A44,'Activity Hours'!$I$4:$T$4,0))) -> 0 | D44: =SUMPRODUCT(('Activity Hours'!$F$5:$F$87=D$39)*INDEX('Activity Hours'!$I$5:$T$87,0,MATCH($A44,'Activity Hours'!$I$4:$T$4,0))) -> 887 | E44: =SUMPRODUCT(('Activity Hours'!$F$5:$F$87=E$39)*INDEX('Activity Hours'!$I$5:$T$87,0,MATCH($A44,'Activity Hours'!$I$4:$T$4,0))) -> 0 | F44: =SUMPRODUCT(('Activity Hours'!$F$5:$F$87=F$39)*INDEX('Activity Hours'!$I$5:$T$87,0,MATCH($A44,'Activity Hours'!$I$4:$T$4,0))) -> 375 | G44: =SUMPRODUCT(('Activity Hours'!$F$5:$F$87=G$39)*INDEX('Activity Hours'!$I$5:$T$87,0,MATCH($A44,'Activity Hours'!$I$4:$T$4,0))) -> 96 | H44: =SUM(C44:G44) -> 1358
A45: AIE | B45: AI / ML Engineer | C45: =SUMPRODUCT(('Activity Hours'!$F$5:$F$87=C$39)*INDEX('Activity Hours'!$I$5:$T$87,0,MATCH($A45,'Activity Hours'!$I$4:$T$4,0))) -> 209 | D45: =SUMPRODUCT(('Activity Hours'!$F$5:$F$87=D$39)*INDEX('Activity Hours'!$I$5:$T$87,0,MATCH($A45,'Activity Hours'!$I$4:$T$4,0))) -> 2969 | E45: =SUMPRODUCT(('Activity Hours'!$F$5:$F$87=E$39)*INDEX('Activity Hours'!$I$5:$T$87,0,MATCH($A45,'Activity Hours'!$I$4:$T$4,0))) -> 32 | F45: =SUMPRODUCT(('Activity Hours'!$F$5:$F$87=F$39)*INDEX('Activity Hours'!$I$5:$T$87,0,MATCH($A45,'Activity Hours'!$I$4:$T$4,0))) -> 2538 | G45: =SUMPRODUCT(('Activity Hours'!$F$5:$F$87=G$39)*INDEX('Activity Hours'!$I$5:$T$87,0,MATCH($A45,'Activity Hours'!$I$4:$T$4,0))) -> 0 | H45: =SUM(C45:G45) -> 5748
...

Sheet Estimate Overview
A1: Estimate overview: 24,000 hours
A2: All figures are live formulas over the Task Breakdown sheet.
A4: Track | B4: Phase 1 | C4: Phase 2 | D4: Phase 3 | E4: Phase 4 | F4: Total hours | G4: % of total
A5: AI Platform Setup | B5: =SUMIFS('Task Breakdown'!$U$5:$U$681,'Task Breakdown'!$C$5:$C$681,$A5,'Task Breakdown'!$D$5:$D$681,"Phase 1") -> 1432 | C5: =SUMIFS('Task Breakdown'!$U$5:$U$681,'Task Breakdown'!$C$5:$C$681,$A5,'Task Breakdown'!$D$5:$D$681,"Phase 2") -> 1792 | D5: =SUMIFS('Task Breakdown'!$U$5:$U$681,'Task Breakdown'!$C$5:$C$681,$A5,'Task Breakdown'!$D$5:$D$681,"Phase 3") -> 2152 | E5: =SUMIFS('Task Breakdown'!$U$5:$U$681,'Task Breakdown'!$C$5:$C$681,$A5,'Task Breakdown'!$D$5:$D$681,"Phase 4") -> 1641 | F5: =SUM(B5:E5) -> 7017 | G5: =IF($F$9>0,F5/$F$9,0) -> 0.292375
A6: AI Data Readiness | B6: =SUMIFS('Task Breakdown'!$U$5:$U$681,'Task Breakdown'!$C$5:$C$681,$A6,'Task Breakdown'!$D$5:$D$681,"Phase 1") -> 858 | C6: =SUMIFS('Task Breakdown'!$U$5:$U$681,'Task Breakdown'!$C$5:$C$681,$A6,'Task Breakdown'!$D$5:$D$681,"Phase 2") -> 2128 | D6: =SUMIFS('Task Breakdown'!$U$5:$U$681,'Task Breakdown'!$C$5:$C$681,$A6,'Task Breakdown'!$D$5:$D$681,"Phase 3") -> 1945 | E6: =SUMIFS('Task Breakdown'!$U$5:$U$681,'Task Breakdown'!$C$5:$C$681,$A6,'Task Breakdown'!$D$5:$D$681,"Phase 4") -> 1131 | F6: =SUM(B6:E6) -> 6062 | G6: =IF($F$9>0,F6/$F$9,0) -> 0.25258333
A7: AI Use Cases | B7: =SUMIFS('Task Breakdown'!$U$5:$U$681,'Task Breakdown'!$C$5:$C$681,$A7,'Task Breakdown'!$D$5:$D$681,"Phase 1") -> 609 | C7: =SUMIFS('Task Breakdown'!$U$5:$U$681,'Task Breakdown'!$C$5:$C$681,$A7,'Task Breakdown'!$D$5:$D$681,"Phase 2") -> 2131 | D7: =SUMIFS('Task Breakdown'!$U$5:$U$681,'Task Breakdown'!$C$5:$C$681,$A7,'Task Breakdown'!$D$5:$D$681,"Phase 3") -> 4270 | E7: =SUMIFS('Task Breakdown'!$U$5:$U$681,'Task Breakdown'!$C$5:$C$681,$A7,'Task Breakdown'!$D$5:$D$681,"Phase 4") -> 2255 | F7: =SUM(B7:E7) -> 9265 | G7: =IF($F$9>0,F7/$F$9,0) -> 0.38604167
A8: Program Management | B8: =SUMIFS('Task Breakdown'!$U$5:$U$681,'Task Breakdown'!$C$5:$C$681,$A8,'Task Breakdown'!$D$5:$D$681,"Phase 1") -> 414 | C8: =SUMIFS('Task Breakdown'!$U$5:$U$681,'Task Breakdown'!$C$5:$C$681,$A8,'Task Breakdown'!$D$5:$D$681,"Phase 2") -> 414 | D8: =SUMIFS('Task Breakdown'!$U$5:$U$681,'Task Breakdown'!$C$5:$C$681,$A8,'Task Breakdown'!$D$5:$D$681,"Phase 3") -> 414 | E8: =SUMIFS('Task Breakdown'!$U$5:$U$681,'Task Breakdown'!$C$5:$C$681,$A8,'Task Breakdown'!$D$5:$D$681,"Phase 4") -> 414 | F8: =SUM(B8:E8) -> 1656 | G8: =IF($F$9>0,F8/$F$9,0) -> 0.069
A9: Total | B9: =SUM(B5:B8) -> 3313 | C9: =SUM(C5:C8) -> 6465 | D9: =SUM(D5:D8) -> 8781 | E9: =SUM(E5:E8) -> 5441 | F9: =SUM(F5:F8) -> 24000 | G9: =SUM(G5:G8) -> 1
A11: Target hours | B11: 24000
A12: Planned minus target | B12: =F9-B11 -> 0 | C12: =IF(B12=0,"On target","Off target: adjust Task Breakdown hours") -> On target
A15: Role mix check
A16: Role | B16: Hours | C16: % of total | D16: Typical range for AI programs | E16: Comment
A17: PM – Program / Project Manager | B17: ='Task Breakdown'!I682 -> 1734 | C17: =IF($F$9>0,B17/$F$9,0) -> 0.07225 | D17: 6–10% | E17: Program across 3 teams and many plants
A18: CA – Cloud / Platform Architect | B18: ='Task Breakdown'!J682 -> 692 | C18: =IF($F$9>0,B18/$F$9,0) -> 0.028833333 | D18: 2–4% | E18: Architecture front-loaded in Phase 1
A19: DO – Platform / DevOps Engineer | B19: ='Task Breakdown'!K682 -> 2649 | C19: =IF($F$9>0,B19/$F$9,0) -> 0.110375 | D19: 8–12% | E19: Landing zone, IaC, DR, plant gateways
A20: SE – Security Engineer | B20: ='Task Breakdown'!L682 -> 1027 | C20: =IF($F$9>0,B20/$F$9,0) -> 0.042791667 | D20: 4–7% | E20: Identity, OT security, pen test, SOX controls
A21: AIA – AI Architect | B21: ='Task Breakdown'!M682 -> 1358 | C21: =IF($F$9>0,B21/$F$9,0) -> 0.056583333 | D21: 4–6% | E21: Design authority for agents and RAG
A22: AIE – AI / ML Engineer | B22: ='Task Breakdown'!N682 -> 5748 | C22: =IF($F$9>0,B22/$F$9,0) -> 0.2395 | D22: 18–25% | E22: Largest role: agents, RAG, gateway, evaluation
A23: DE – Data Engineer | B23: ='Task Breakdown'!O682 -> 2935 | C23: =IF($F$9>0,B23/$F$9,0) -> 0.12229167 | D23: 10–15% | E23: SAP, MES, PI pipelines and plant onboarding
A24: DG – Data Architect / Governance | B24: ='Task Breakdown'!P682 -> 754 | C24: =IF($F$9>0,B24/$F$9,0) -> 0.031416667 | D24: 2–4% | E24: Classification, catalog, lineage
A25: DEV – Full-stack Developer | B25: ='Task Breakdown'!Q682 -> 2031 | C25: =IF($F$9>0,B25/$F$9,0) -> 0.084625 | D25: 7–10% | E25: Teams app, web, mobile, admin panel
A26: BA – Business Analyst / Product Owner | B26: ='Task Breakdown'!R682 -> 2225 | C26: =IF($F$9>0,B26/$F$9,0) -> 0.092708333 | D26: 8–12% | E26: Requirements, KPIs, golden test sets
A27: QA – QA / Test Engineer | B27: ='Task Breakdown'!S682 -> 2259 | C27: =IF($F$9>0,B27/$F$9,0) -> 0.094125 | D27: 9–13% | E27: Testing inside every item
A28: CM – Change & Training Lead | B28: ='Task Breakdown'!T682 -> 588 | C28: =IF($F$9>0,B28/$F$9,0) -> 0.0245 | D28: 2–4% | E28: Training and adoption across plants

Sheet Phase 1
A1: Phase 1: tasks and hours for each item (Foundation / Assess / Discover)
A2: Bold rows are the slide items; the rows beneath are their implementation tasks (green = linked to Task Breakdown).
A4: ID | B4: Item / task | C4: Owner team | D4: Deliverable | E4: PM | F4: CA | G4: DO | H4: SE | I4: AIA | J4: AIE | K4: DE | L4: DG | M4: DEV | N4: BA | O4: QA | P4: CM | Q4: Total hours | R4: % of phase
A5: AI Platform Setup: Foundation
A6: PS-1.01 | B6: Azure landing zone, subscriptions, VNets, private endpoints | C6: Platform Engineering | D6: Landing zone deployed | E6: =SUM(E7:E18) -> 0 | F6: =SUM(F7:F18) -> 77 | G6: =SUM(G7:G18) -> 197 | H6: =SUM(H7:H18) -> 40 | I6: =SUM(I7:I18) -> 0 | J6: =SUM(J7:J18) -> 0 | K6: =SUM(K7:K18) -> 0 | L6: =SUM(L7:L18) -> 0 | ... Q6: =SUM(Q7:Q18) -> 334 | R6: =IF($Q$183>0,Q6/$Q$183,0) -> 0.10081497
A7: ='Task Breakdown'!A5 -> PS-1.01.01 | B7: ='Task Breakdown'!G5 -> Define management-group and subscription hierarchy (prod, non-prod, sandbox) | E7: ='Task Breakdown'!I5 -> 0 | F7: ='Task Breakdown'!J5 -> 15 | G7: ='Task Breakdown'!K5 -> 0 | H7: ='Task Breakdown'!L5 -> 0 | I7: ='Task Breakdown'!M5 -> 0 | J7: ='Task Breakdown'!N5 -> 0 | K7: ='Task Breakdown'!O5 -> 0 | L7: ='Task Breakdown'!P5 -> 0 | ... P7: ='Task Breakdown'!T5 -> 0 | Q7: =SUM(E7:P7) -> 15 | R7: =IF($Q$183>0,Q7/$Q$183,0) -> 0.0045276185
A8: ='Task Breakdown'!A6 -> PS-1.01.02 | B8: ='Task Breakdown'!G6 -> Design hub-and-spoke network, IP address plan and DNS | E8: ='Task Breakdown'!I6 -> 0 | F8: ='Task Breakdown'!J6 -> 20 | G8: ='Task Breakdown'!K6 -> 10 | H8: ='Task Breakdown'!L6 -> 0 | I8: ='Task Breakdown'!M6 -> 0 | J8: ='Task Breakdown'!N6 -> 0 | K8: ='Task Breakdown'!O6 -> 0 | L8: ='Task Breakdown'!P6 -> 0 | ... P8: ='Task Breakdown'!T6 -> 0 | Q8: =SUM(E8:P8) -> 30 | R8: =IF($Q$183>0,Q8/$Q$183,0) -> 0.0090552369
A9: ='Task Breakdown'!A7 -> PS-1.01.03 | B9: ='Task Breakdown'!G7 -> Deploy hub VNet, Azure Firewall and spoke VNets | E9: ='Task Breakdown'!I7 -> 0 | F9: ='Task Breakdown'!J7 -> 0 | G9: ='Task Breakdown'!K7 -> 41 | H9: ='Task Breakdown'!L7 -> 0 | I9: ='Task Breakdown'!M7 -> 0 | J9: ='Task Breakdown'!N7 -> 0 | K9: ='Task Breakdown'!O7 -> 0 | L9: ='Task Breakdown'!P7 -> 0 | ... P9: ='Task Breakdown'!T7 -> 0 | Q9: =SUM(E9:P9) -> 41 | R9: =IF($Q$183>0,Q9/$Q$183,0) -> 0.01237549
A10: ='Task Breakdown'!A8 -> PS-1.01.04 | B10: ='Task Breakdown'!G8 -> Set up ExpressRoute / VPN to Ball data centers and plants | E10: ='Task Breakdown'!I8 -> 0 | F10: ='Task Breakdown'!J8 -> 10 | G10: ='Task Breakdown'!K8 -> 31 | H10: ='Task Breakdown'!L8 -> 5 | I10: ='Task Breakdown'!M8 -> 0 | J10: ='Task Breakdown'!N8 -> 0 | K10: ='Task Breakdown'!O8 -> 0 | L10: ='Task Breakdown'!P8 -> 0 | ... P10: ='Task Breakdown'!T8 -> 0 | Q10: =SUM(E10:P10) -> 46 | R10: =IF($Q$183>0,Q10/$Q$183,0) -> 0.013884697
A11: ='Task Breakdown'!A9 -> PS-1.01.05 | B11: ='Task Breakdown'!G9 -> Configure private endpoints and private DNS zones for PaaS services | E11: ='Task Breakdown'!I9 -> 0 | F11: ='Task Breakdown'!J9 -> 0 | G11: ='Task Breakdown'!K9 -> 41 | H11: ='Task Breakdown'!L9 -> 10 | I11: ='Task Breakdown'!M9 -> 0 | J11: ='Task Breakdown'!N9 -> 0 | K11: ='Task Breakdown'!O9 -> 0 | L11: ='Task Breakdown'!P9 -> 0 | ... P11: ='Task Breakdown'!T9 -> 0 | Q11: =SUM(E11:P11) -> 51 | R11: =IF($Q$183>0,Q11/$Q$183,0) -> 0.015393903
A12: ='Task Breakdown'!A10 -> PS-1.01.06 | B12: ='Task Breakdown'!G10 -> Apply Azure Policy baseline (allowed regions, tagging, no public IPs) | E12: ='Task Breakdown'!I10 -> 0 | F12: ='Task Breakdown'!J10 -> 5 | G12: ='Task Breakdown'!K10 -> 20 | H12: ='Task Breakdown'!L10 -> 15 | I12: ='Task Breakdown'!M10 -> 0 | J12: ='Task Breakdown'!N10 -> 0 | K12: ='Task Breakdown'!O10 -> 0 | L12: ='Task Breakdown'!P10 -> 0 | ... P12: ='Task Breakdown'!T10 -> 0 | Q12: =SUM(E12:P12) -> 40 | R12: =IF($Q$183>0,Q12/$Q$183,0) -> 0.012073649
A13: ='Task Breakdown'!A11 -> PS-1.01.07 | B13: ='Task Breakdown'!G11 -> Enable Defender for Cloud and diagnostic settings | E13: ='Task Breakdown'!I11 -> 0 | F13: ='Task Breakdown'!J11 -> 0 | G13: ='Task Breakdown'!K11 -> 10 | H13: ='Task Breakdown'!L11 -> 10 | I13: ='Task Breakdown'!M11 -> 0 | J13: ='Task Breakdown'!N11 -> 0 | K13: ='Task Breakdown'!O11 -> 0 | L13: ='Task Breakdown'!P11 -> 0 | ... P13: ='Task Breakdown'!T11 -> 0 | Q13: =SUM(E13:P13) -> 20 | R13: =IF($Q$183>0,Q13/$Q$183,0) -> 0.0060368246
A14: ='Task Breakdown'!A12 -> PS-1.01.08 | B14: ='Task Breakdown'!G12 -> Validate connectivity and policy compliance | E14: ='Task Breakdown'!I12 -> 0 | F14: ='Task Breakdown'!J12 -> 10 | G14: ='Task Breakdown'!K12 -> 0 | H14: ='Task Breakdown'!L12 -> 0 | I14: ='Task Breakdown'!M12 -> 0 | J14: ='Task Breakdown'!N12 -> 0 | K14: ='Task Breakdown'!O12 -> 0 | L14: ='Task Breakdown'!P12 -> 0 | ... P14: ='Task Breakdown'!T12 -> 0 | Q14: =SUM(E14:P14) -> 30 | R14: =IF($Q$183>0,Q14/$Q$183,0) -> 0.0090552369
A15: ='Task Breakdown'!A13 -> PS-1.01.09 | B15: ='Task Breakdown'!G13 -> Detailed design and design review | E15: ='Task Breakdown'!I13 -> 0 | F15: ='Task Breakdown'!J13 -> 17 | G15: ='Task Breakdown'!K13 -> 0 | H15: ='Task Breakdown'!L13 -> 0 | I15: ='Task Breakdown'!M13 -> 0 | J15: ='Task Breakdown'!N13 -> 0 | K15: ='Task Breakdown'!O13 -> 0 | L15: ='Task Breakdown'!P13 -> 0 | ... P15: ='Task Breakdown'!T13 -> 0 | Q15: =SUM(E15:P15) -> 17 | R15: =IF($Q$183>0,Q15/$Q$183,0) -> 0.0051313009
A16: ='Task Breakdown'!A14 -> PS-1.01.10 | B16: ='Task Breakdown'!G14 -> Promote through dev / test / prod and release | E16: ='Task Breakdown'!I14 -> 0 | F16: ='Task Breakdown'!J14 -> 0 | G16: ='Task Breakdown'!K14 -> 11 | H16: ='Task Breakdown'!L14 -> 0 | I16: ='Task Breakdown'!M14 -> 0 | J16: ='Task Breakdown'!N14 -> 0 | K16: ='Task Breakdown'!O14 -> 0 | L16: ='Task Breakdown'!P14 -> 0 | ... P16: ='Task Breakdown'!T14 -> 0 | Q16: =SUM(E16:P16) -> 11 | R16: =IF($Q$183>0,Q16/$Q$183,0) -> 0.0033202535
A17: ='Task Breakdown'!A15 -> PS-1.01.11 | B17: ='Task Breakdown'!G15 -> Documentation, runbook and knowledge transfer | E17: ='Task Breakdown'!I15 -> 0 | F17: ='Task Breakdown'!J15 -> 0 | G17: ='Task Breakdown'!K15 -> 11 | H17: ='Task Breakdown'!L15 -> 0 | I17: ='Task Breakdown'!M15 -> 0 | J17: ='Task Breakdown'!N15 -> 0 | K17: ='Task Breakdown'!O15 -> 0 | L17: ='Task Breakdown'!P15 -> 0 | ... P17: ='Task Breakdown'!T15 -> 0 | Q17: =SUM(E17:P17) -> 11 | R17: =IF($Q$183>0,Q17/$Q$183,0) -> 0.0033202535
A18: ='Task Breakdown'!A16 -> PS-1.01.12 | B18: ='Task Breakdown'!G16 -> Defect fixing and rework after testing | E18: ='Task Breakdown'!I16 -> 0 | F18: ='Task Breakdown'!J16 -> 0 | G18: ='Task Breakdown'!K16 -> 22 | H18: ='Task Breakdown'!L16 -> 0 | I18: ='Task Breakdown'!M16 -> 0 | J18: ='Task Breakdown'!N16 -> 0 | K18: ='Task Breakdown'!O16 -> 0 | L18: ='Task Breakdown'!P16 -> 0 | ... P18: ='Task Breakdown'!T16 -> 0 | Q18: =SUM(E18:P18) -> 22 | R18: =IF($Q$183>0,Q18/$Q$183,0) -> 0.0066405071
A19: PS-1.02 | B19: Entra ID SSO, MFA / PIM, conditional access | C19: Platform Engineering | D19: Identity and access configuration | E19: =SUM(E20:E27) -> 0 | F19: =SUM(F20:F27) -> 24 | G19: =SUM(G20:G27) -> 16 | H19: =SUM(H20:H27) -> 89 | I19: =SUM(I20:I27) -> 0 | J19: =SUM(J20:J27) -> 0 | K19: =SUM(K20:K27) -> 0 | L19: =SUM(L20:L27) -> 0 | ... Q19: =SUM(Q20:Q27) -> 145 | R19: =IF($Q$183>0,Q19/$Q$183,0) -> 0.043766979
A20: ='Task Breakdown'!A17 -> PS-1.02.01 | B20: ='Task Breakdown'!G17 -> Register enterprise apps and app registrations for platform services | E20: ='Task Breakdown'!I17 -> 0 | F20: ='Task Breakdown'!J17 -> 0 | G20: ='Task Breakdown'!K17 -> 8 | H20: ='Task Breakdown'!L17 -> 12 | I20: ='Task Breakdown'!M17 -> 0 | J20: ='Task Breakdown'!N17 -> 0 | K20: ='Task Breakdown'!O17 -> 0 | L20: ='Task Breakdown'!P17 -> 0 | ... P20: ='Task Breakdown'!T17 -> 0 | Q20: =SUM(E20:P20) -> 20 | R20: =IF($Q$183>0,Q20/$Q$183,0) -> 0.0060368246
A21: ='Task Breakdown'!A18 -> PS-1.02.02 | B21: ='Task Breakdown'!G18 -> Configure SSO (OIDC / SAML) for web, mobile and Teams clients | E21: ='Task Breakdown'!I18 -> 0 | F21: ='Task Breakdown'!J18 -> 0 | G21: ='Task Breakdown'!K18 -> 8 | H21: ='Task Breakdown'!L18 -> 20 | I21: ='Task Breakdown'!M18 -> 0 | J21: ='Task Breakdown'!N18 -> 0 | K21: ='Task Breakdown'!O18 -> 0 | L21: ='Task Breakdown'!P18 -> 0 | ... P21: ='Task Breakdown'!T18 -> 0 | Q21: =SUM(E21:P21) -> 28 | R21: =IF($Q$183>0,Q21/$Q$183,0) -> 0.0084515545
A22: ='Task Breakdown'!A19 -> PS-1.02.03 | B22: ='Task Breakdown'!G19 -> Enforce MFA and create conditional access policies (device, location, risk) | E22: ='Task Breakdown'!I19 -> 0 | F22: ='Task Breakdown'!J19 -> 8 | G22: ='Task Breakdown'!K19 -> 0 | H22: ='Task Breakdown'!L19 -> 20 | I22: ='Task Breakdown'!M19 -> 0 | J22: ='Task Breakdown'!N19 -> 0 | K22: ='Task Breakdown'!O19 -> 0 | L22: ='Task Breakdown'!P19 -> 0 | ... P22: ='Task Breakdown'!T19 -> 0 | Q22: =SUM(E22:P22) -> 28 | R22: =IF($Q$183>0,Q22/$Q$183,0) -> 0.0084515545
A23: ='Task Breakdown'!A20 -> PS-1.02.04 | B23: ='Task Breakdown'!G20 -> Set up PIM for privileged roles with approval and time limits | E23: ='Task Breakdown'!I20 -> 0 | F23: ='Task Breakdown'!J20 -> 0 | G23: ='Task Breakdown'!K20 -> 0 | H23: ='Task Breakdown'!L20 -> 16 | I23: ='Task Breakdown'!M20 -> 0 | J23: ='Task Breakdown'!N20 -> 0 | K23: ='Task Breakdown'!O20 -> 0 | L23: ='Task Breakdown'!P20 -> 0 | ... P23: ='Task Breakdown'!T20 -> 0 | Q23: =SUM(E23:P23) -> 16 | R23: =IF($Q$183>0,Q23/$Q$183,0) -> 0.0048294597
A24: ='Task Breakdown'!A21 -> PS-1.02.05 | B24: ='Task Breakdown'!G21 -> Create managed identities for services and agents | E24: ='Task Breakdown'!I21 -> 0 | F24: ='Task Breakdown'!J21 -> 8 | G24: ='Task Breakdown'!K21 -> 0 | H24: ='Task Breakdown'!L21 -> 12 | I24: ='Task Breakdown'!M21 -> 0 | J24: ='Task Breakdown'!N21 -> 0 | K24: ='Task Breakdown'!O21 -> 0 | L24: ='Task Breakdown'!P21 -> 0 | ... P24: ='Task Breakdown'!T21 -> 0 | Q24: =SUM(E24:P24) -> 20 | R24: =IF($Q$183>0,Q24/$Q$183,0) -> 0.0060368246
A25: ='Task Breakdown'!A22 -> PS-1.02.06 | B25: ='Task Breakdown'!G22 -> Test sign-in flows and break-glass accounts | E25: ='Task Breakdown'!I22 -> 0 | F25: ='Task Breakdown'!J22 -> 0 | G25: ='Task Breakdown'!K22 -> 0 | H25: ='Task Breakdown'!L22 -> 4 | I25: ='Task Breakdown'!M22 -> 0 | J25: ='Task Breakdown'!N22 -> 0 | K25: ='Task Breakdown'!O22 -> 0 | L25: ='Task Breakdown'!P22 -> 0 | ... P25: ='Task Breakdown'!T22 -> 0 | Q25: =SUM(E25:P25) -> 20 | R25: =IF($Q$183>0,Q25/$Q$183,0) -> 0.0060368246
A26: ='Task Breakdown'!A23 -> PS-1.02.07 | B26: ='Task Breakdown'!G23 -> Detailed design and design review | E26: ='Task Breakdown'!I23 -> 0 | F26: ='Task Breakdown'!J23 -> 8 | G26: ='Task Breakdown'!K23 -> 0 | H26: ='Task Breakdown'!L23 -> 0 | I26: ='Task Breakdown'!M23 -> 0 | J26: ='Task Breakdown'!N23 -> 0 | K26: ='Task Breakdown'!O23 -> 0 | L26: ='Task Breakdown'!P23 -> 0 | ... P26: ='Task Breakdown'!T23 -> 0 | Q26: =SUM(E26:P26) -> 8 | R26: =IF($Q$183>0,Q26/$Q$183,0) -> 0.0024147299
A27: ='Task Breakdown'!A24 -> PS-1.02.08 | B27: ='Task Breakdown'!G24 -> Documentation, runbook and knowledge transfer | E27: ='Task Breakdown'!I24 -> 0 | F27: ='Task Breakdown'!J24 -> 0 | G27: ='Task Breakdown'!K24 -> 0 | H27: ='Task Breakdown'!L24 -> 5 | I27: ='Task Breakdown'!M24 -> 0 | J27: ='Task Breakdown'!N24 -> 0 | K27: ='Task Breakdown'!O24 -> 0 | L27: ='Task Breakdown'!P24 -> 0 | ... P27: ='Task Breakdown'!T24 -> 0 | Q27: =SUM(E27:P27) -> 5 | R27: =IF($Q$183>0,Q27/$Q$183,0) -> 0.0015092062
A28: PS-1.03 | B28: RBAC / ABAC roles and fine-grained permissions | C28: Platform Engineering | D28: Role and permission matrix | E28: =SUM(E29:E35) -> 0 | F28: =SUM(F29:F35) -> 27 | G28: =SUM(G29:G35) -> 0 | H28: =SUM(H29:H35) -> 86 | I28: =SUM(I29:I35) -> 0 | J28: =SUM(J29:J35) -> 0 | K28: =SUM(K29:K35) -> 0 | L28: =SUM(L29:L35) -> 0 | ... Q28: =SUM(Q29:Q35) -> 133 | R28: =IF($Q$183>0,Q28/$Q$183,0) -> 0.040144884
A29: ='Task Breakdown'!A25 -> PS-1.03.01 | B29: ='Task Breakdown'!G25 -> Gather personas and access needs (plant ops, engineers, analysts, admins) | E29: ='Task Breakdown'!I25 -> 0 | F29: ='Task Breakdown'!J25 -> 0 | G29: ='Task Breakdown'!K25 -> 0 | H29: ='Task Breakdown'!L25 -> 10 | I29: ='Task Breakdown'!M25 -> 0 | J29: ='Task Breakdown'!N25 -> 0 | K29: ='Task Breakdown'!O25 -> 0 | L29: ='Task Breakdown'!P25 -> 0 | ... P29: ='Task Breakdown'!T25 -> 0 | Q29: =SUM(E29:P29) -> 30 | R29: =IF($Q$183>0,Q29/$Q$183,0) -> 0.0090552369
A30: ='Task Breakdown'!A26 -> PS-1.03.02 | B30: ='Task Breakdown'!G26 -> Design role model and permission matrix (RBAC + ABAC attributes: plant, region, function) | E30: ='Task Breakdown'!I26 -> 0 | F30: ='Task Breakdown'!J26 -> 15 | G30: ='Task Breakdown'!K26 -> 0 | H30: ='Task Breakdown'!L26 -> 26 | I30: ='Task Breakdown'!M26 -> 0 | J30: ='Task Breakdown'!N26 -> 0 | K30: ='Task Breakdown'!O26 -> 0 | L30: ='Task Breakdown'!P26 -> 0 | ... P30: ='Task Breakdown'!T26 -> 0 | Q30: =SUM(E30:P30) -> 41 | R30: =IF($Q$183>0,Q30/$Q$183,0) -> 0.01237549
A31: ='Task Breakdown'!A27 -> PS-1.03.03 | B31: ='Task Breakdown'!G27 -> Create Entra security groups and custom Azure roles | E31: ='Task Breakdown'!I27 -> 0 | F31: ='Task Breakdown'!J27 -> 0 | G31: ='Task Breakdown'!K27 -> 0 | H31: ='Task Breakdown'!L27 -> 20 | I31: ='Task Breakdown'!M27 -> 0 | J31: ='Task Breakdown'!N27 -> 0 | K31: ='Task Breakdown'!O27 -> 0 | L31: ='Task Breakdown'!P27 -> 0 | ... P31: ='Task Breakdown'!T27 -> 0 | Q31: =SUM(E31:P31) -> 20 | R31: =IF($Q$183>0,Q31/$Q$183,0) -> 0.0060368246
A32: ='Task Breakdown'!A28 -> PS-1.03.04 | B32: ='Task Breakdown'!G28 -> Map agent and tool permissions to roles | E32: ='Task Breakdown'!I28 -> 0 | F32: ='Task Breakdown'!J28 -> 5 | G32: ='Task Breakdown'!K28 -> 0 | H32: ='Task Breakdown'!L28 -> 15 | I32: ='Task Breakdown'!M28 -> 0 | J32: ='Task Breakdown'!N28 -> 0 | K32: ='Task Breakdown'!O28 -> 0 | L32: ='Task Breakdown'!P28 -> 0 | ... P32: ='Task Breakdown'!T28 -> 0 | Q32: =SUM(E32:P32) -> 20 | R32: =IF($Q$183>0,Q32/$Q$183,0) -> 0.0060368246
A33: ='Task Breakdown'!A29 -> PS-1.03.05 | B33: ='Task Breakdown'!G29 -> Document access request and periodic access review process | E33: ='Task Breakdown'!I29 -> 0 | F33: ='Task Breakdown'!J29 -> 0 | G33: ='Task Breakdown'!K29 -> 0 | H33: ='Task Breakdown'!L29 -> 10 | I33: ='Task Breakdown'!M29 -> 0 | J33: ='Task Breakdown'!N29 -> 0 | K33: ='Task Breakdown'!O29 -> 0 | L33: ='Task Breakdown'!P29 -> 0 | ... P33: ='Task Breakdown'!T29 -> 0 | Q33: =SUM(E33:P33) -> 10 | R33: =IF($Q$183>0,Q33/$Q$183,0) -> 0.0030184123
A34: ='Task Breakdown'!A30 -> PS-1.03.06 | B34: ='Task Breakdown'!G30 -> Detailed design and design review | E34: ='Task Breakdown'!I30 -> 0 | F34: ='Task Breakdown'!J30 -> 7 | G34: ='Task Breakdown'!K30 -> 0 | H34: ='Task Breakdown'!L30 -> 0 | I34: ='Task Breakdown'!M30 -> 0 | J34: ='Task Breakdown'!N30 -> 0 | K34: ='Task Breakdown'!O30 -> 0 | L34: ='Task Breakdown'!P30 -> 0 | ... P34: ='Task Breakdown'!T30 -> 0 | Q34: =SUM(E34:P34) -> 7 | R34: =IF($Q$183>0,Q34/$Q$183,0) -> 0.0021128886
A35: ='Task Breakdown'!A31 -> PS-1.03.07 | B35: ='Task Breakdown'!G31 -> Documentation, runbook and knowledge transfer | E35: ='Task Breakdown'!I31 -> 0 | F35: ='Task Breakdown'!J31 -> 0 | G35: ='Task Breakdown'!K31 -> 0 | H35: ='Task Breakdown'!L31 -> 5 | I35: ='Task Breakdown'!M31 -> 0 | J35: ='Task Breakdown'!N31 -> 0 | K35: ='Task Breakdown'!O31 -> 0 | L35: ='Task Breakdown'!P31 -> 0 | ... P35: ='Task Breakdown'!T31 -> 0 | Q35: =SUM(E35:P35) -> 5 | R35: =IF($Q$183>0,Q35/$Q$183,0) -> 0.0015092062
A36: PS-1.04 | B36: Key Vault, TDE / TLS encryption | C36: Platform Engineering | D36: Key and secret management in place | E36: =SUM(E37:E43) -> 0 | F36: =SUM(F37:F43) -> 5 | G36: =SUM(G37:G43) -> 32 | H36: =SUM(H37:H43) -> 51 | I36: =SUM(I37:I43) -> 0 | J36: =SUM(J37:J43) -> 0 | K36: =SUM(K37:K43) -> 0 | L36: =SUM(L37:L43) -> 0 | ... Q36: =SUM(Q37:Q43) -> 88 | R36: =IF($Q$183>0,Q36/$Q$183,0) -> 0.026562028
A37: ='Task Breakdown'!A32 -> PS-1.04.01 | B37: ='Task Breakdown'!G32 -> Deploy Key Vaults per environment with private endpoints | E37: ='Task Breakdown'!I32 -> 0 | F37: ='Task Breakdown'!J32 -> 0 | G37: ='Task Breakdown'!K32 -> 12 | H37: ='Task Breakdown'!L32 -> 4 | I37: ='Task Breakdown'!M32 -> 0 | J37: ='Task Breakdown'!N32 -> 0 | K37: ='Task Breakdown'!O32 -> 0 | L37: ='Task Breakdown'!P32 -> 0 | ... P37: ='Task Breakdown'!T32 -> 0 | Q37: =SUM(E37:P37) -> 16 | R37: =IF($Q$183>0,Q37/$Q$183,0) -> 0.0048294597
A38: ='Task Breakdown'!A33 -> PS-1.04.02 | B38: ='Task Breakdown'!G33 -> Define secret, key and certificate naming and rotation policy | E38: ='Task Breakdown'!I33 -> 0 | F38: ='Task Breakdown'!J33 -> 0 | G38: ='Task Breakdown'!K33 -> 0 | H38: ='Task Breakdown'!L33 -> 12 | I38: ='Task Breakdown'!M33 -> 0 | J38: ='Task Breakdown'!N33 -> 0 | K38: ='Task Breakdown'!O33 -> 0 | L38: ='Task Breakdown'!P33 -> 0 | ... P38: ='Task Breakdown'!T33 -> 0 | Q38: =SUM(E38:P38) -> 12 | R38: =IF($Q$183>0,Q38/$Q$183,0) -> 0.0036220948
A39: ='Task Breakdown'!A34 -> PS-1.04.03 | B39: ='Task Breakdown'!G34 -> Enable TDE with customer-managed keys on SQL, PostgreSQL and Storage | E39: ='Task Breakdown'!I34 -> 0 | F39: ='Task Breakdown'!J34 -> 0 | G39: ='Task Breakdown'!K34 -> 8 | H39: ='Task Breakdown'!L34 -> 16 | I39: ='Task Breakdown'!M34 -> 0 | J39: ='Task Breakdown'!N34 -> 0 | K39: ='Task Breakdown'!O34 -> 0 | L39: ='Task Breakdown'!P34 -> 0 | ... P39: ='Task Breakdown'!T34 -> 0 | Q39: =SUM(E39:P39) -> 24 | R39: =IF($Q$183>0,Q39/$Q$183,0) -> 0.0072441896
A40: ='Task Breakdown'!A35 -> PS-1.04.04 | B40: ='Task Breakdown'!G35 -> Enforce TLS 1.2+ and manage certificates for custom domains | E40: ='Task Breakdown'!I35 -> 0 | F40: ='Task Breakdown'!J35 -> 0 | G40: ='Task Breakdown'!K35 -> 8 | H40: ='Task Breakdown'!L35 -> 8 | I40: ='Task Breakdown'!M35 -> 0 | J40: ='Task Breakdown'!N35 -> 0 | K40: ='Task Breakdown'!O35 -> 0 | L40: ='Task Breakdown'!P35 -> 0 | ... P40: ='Task Breakdown'!T35 -> 0 | Q40: =SUM(E40:P40) -> 16 | R40: =IF($Q$183>0,Q40/$Q$183,0) -> 0.0048294597
A41: ='Task Breakdown'!A36 -> PS-1.04.05 | B41: ='Task Breakdown'!G36 -> Configure vault RBAC and audit logging | E41: ='Task Breakdown'!I36 -> 0 | F41: ='Task Breakdown'!J36 -> 0 | G41: ='Task Breakdown'!K36 -> 4 | H41: ='Task Breakdown'!L36 -> 8 | I41: ='Task Breakdown'!M36 -> 0 | J41: ='Task Breakdown'!N36 -> 0 | K41: ='Task Breakdown'!O36 -> 0 | L41: ='Task Breakdown'!P36 -> 0 | ... P41: ='Task Breakdown'!T36 -> 0 | Q41: =SUM(E41:P41) -> 12 | R41: =IF($Q$183>0,Q41/$Q$183,0) -> 0.0036220948
...

Sheet Phase 2
A1: Phase 2: tasks and hours for each item (Core AI build / Prepare / Pilot)
A2: Bold rows are the slide items; the rows beneath are their implementation tasks (green = linked to Task Breakdown).
A4: ID | B4: Item / task | C4: Owner team | D4: Deliverable | E4: PM | F4: CA | G4: DO | H4: SE | I4: AIA | J4: AIE | K4: DE | L4: DG | M4: DEV | N4: BA | O4: QA | P4: CM | Q4: Total hours | R4: % of phase
A5: AI Platform Setup: Core AI build
A6: PS-2.01 | B6: AI Foundry hub and projects | C6: Foundry | D6: Foundry hub, projects, connections | E6: =SUM(E7:E16) -> 0 | F6: =SUM(F7:F16) -> 0 | G6: =SUM(G7:G16) -> 37 | H6: =SUM(H7:H16) -> 16 | I6: =SUM(I7:I16) -> 40 | J6: =SUM(J7:J16) -> 64 | K6: =SUM(K7:K16) -> 0 | L6: =SUM(L7:L16) -> 0 | ... Q6: =SUM(Q7:Q16) -> 157 | R6: =IF($Q$216>0,Q6/$Q$216,0) -> 0.024284609
A7: ='Task Breakdown'!A71 -> PS-2.01.01 | B7: ='Task Breakdown'!G71 -> Design Foundry hub and project structure per domain and environment | E7: ='Task Breakdown'!I71 -> 0 | F7: ='Task Breakdown'!J71 -> 0 | G7: ='Task Breakdown'!K71 -> 0 | H7: ='Task Breakdown'!L71 -> 0 | I7: ='Task Breakdown'!M71 -> 16 | J7: ='Task Breakdown'!N71 -> 0 | K7: ='Task Breakdown'!O71 -> 0 | L7: ='Task Breakdown'!P71 -> 0 | ... P7: ='Task Breakdown'!T71 -> 0 | Q7: =SUM(E7:P7) -> 16 | R7: =IF($Q$216>0,Q7/$Q$216,0) -> 0.0024748647
A8: ='Task Breakdown'!A72 -> PS-2.01.02 | B8: ='Task Breakdown'!G72 -> Deploy Foundry hub with managed VNet and private endpoints | E8: ='Task Breakdown'!I72 -> 0 | F8: ='Task Breakdown'!J72 -> 0 | G8: ='Task Breakdown'!K72 -> 20 | H8: ='Task Breakdown'!L72 -> 8 | I8: ='Task Breakdown'!M72 -> 0 | J8: ='Task Breakdown'!N72 -> 0 | K8: ='Task Breakdown'!O72 -> 0 | L8: ='Task Breakdown'!P72 -> 0 | ... P8: ='Task Breakdown'!T72 -> 0 | Q8: =SUM(E8:P8) -> 28 | R8: =IF($Q$216>0,Q8/$Q$216,0) -> 0.0043310131
A9: ='Task Breakdown'!A73 -> PS-2.01.03 | B9: ='Task Breakdown'!G73 -> Create projects and connect AI Search, Storage, Key Vault, App Insights | E9: ='Task Breakdown'!I73 -> 0 | F9: ='Task Breakdown'!J73 -> 0 | G9: ='Task Breakdown'!K73 -> 12 | H9: ='Task Breakdown'!L73 -> 0 | I9: ='Task Breakdown'!M73 -> 0 | J9: ='Task Breakdown'!N73 -> 20 | K9: ='Task Breakdown'!O73 -> 0 | L9: ='Task Breakdown'!P73 -> 0 | ... P9: ='Task Breakdown'!T73 -> 0 | Q9: =SUM(E9:P9) -> 32 | R9: =IF($Q$216>0,Q9/$Q$216,0) -> 0.0049497293
A10: ='Task Breakdown'!A74 -> PS-2.01.04 | B10: ='Task Breakdown'!G74 -> Deploy base chat and embedding models with capacity / PTU plan | E10: ='Task Breakdown'!I74 -> 0 | F10: ='Task Breakdown'!J74 -> 0 | G10: ='Task Breakdown'!K74 -> 0 | H10: ='Task Breakdown'!L74 -> 0 | I10: ='Task Breakdown'!M74 -> 8 | J10: ='Task Breakdown'!N74 -> 16 | K10: ='Task Breakdown'!O74 -> 0 | L10: ='Task Breakdown'!P74 -> 0 | ... P10: ='Task Breakdown'!T74 -> 0 | Q10: =SUM(E10:P10) -> 24 | R10: =IF($Q$216>0,Q10/$Q$216,0) -> 0.003712297
A11: ='Task Breakdown'!A75 -> PS-2.01.05 | B11: ='Task Breakdown'!G75 -> Set up project RBAC and developer access | E11: ='Task Breakdown'!I75 -> 0 | F11: ='Task Breakdown'!J75 -> 0 | G11: ='Task Breakdown'!K75 -> 0 | H11: ='Task Breakdown'!L75 -> 8 | I11: ='Task Breakdown'!M75 -> 4 | J11: ='Task Breakdown'!N75 -> 0 | K11: ='Task Breakdown'!O75 -> 0 | L11: ='Task Breakdown'!P75 -> 0 | ... P11: ='Task Breakdown'!T75 -> 0 | Q11: =SUM(E11:P11) -> 12 | R11: =IF($Q$216>0,Q11/$Q$216,0) -> 0.0018561485
A12: ='Task Breakdown'!A76 -> PS-2.01.06 | B12: ='Task Breakdown'!G76 -> Smoke-test model endpoints from the SDK | E12: ='Task Breakdown'!I76 -> 0 | F12: ='Task Breakdown'!J76 -> 0 | G12: ='Task Breakdown'!K76 -> 0 | H12: ='Task Breakdown'!L76 -> 0 | I12: ='Task Breakdown'!M76 -> 4 | J12: ='Task Breakdown'!N76 -> 12 | K12: ='Task Breakdown'!O76 -> 0 | L12: ='Task Breakdown'!P76 -> 0 | ... P12: ='Task Breakdown'!T76 -> 0 | Q12: =SUM(E12:P12) -> 16 | R12: =IF($Q$216>0,Q12/$Q$216,0) -> 0.0024748647
A13: ='Task Breakdown'!A77 -> PS-2.01.07 | B13: ='Task Breakdown'!G77 -> Detailed design and design review | E13: ='Task Breakdown'!I77 -> 0 | F13: ='Task Breakdown'!J77 -> 0 | G13: ='Task Breakdown'!K77 -> 0 | H13: ='Task Breakdown'!L77 -> 0 | I13: ='Task Breakdown'!M77 -> 8 | J13: ='Task Breakdown'!N77 -> 0 | K13: ='Task Breakdown'!O77 -> 0 | L13: ='Task Breakdown'!P77 -> 0 | ... P13: ='Task Breakdown'!T77 -> 0 | Q13: =SUM(E13:P13) -> 8 | R13: =IF($Q$216>0,Q13/$Q$216,0) -> 0.0012374323
A14: ='Task Breakdown'!A78 -> PS-2.01.08 | B14: ='Task Breakdown'!G78 -> Promote through dev / test / prod and release | E14: ='Task Breakdown'!I78 -> 0 | F14: ='Task Breakdown'!J78 -> 0 | G14: ='Task Breakdown'!K78 -> 5 | H14: ='Task Breakdown'!L78 -> 0 | I14: ='Task Breakdown'!M78 -> 0 | J14: ='Task Breakdown'!N78 -> 0 | K14: ='Task Breakdown'!O78 -> 0 | L14: ='Task Breakdown'!P78 -> 0 | ... P14: ='Task Breakdown'!T78 -> 0 | Q14: =SUM(E14:P14) -> 5 | R14: =IF($Q$216>0,Q14/$Q$216,0) -> 0.0007733952
A15: ='Task Breakdown'!A79 -> PS-2.01.09 | B15: ='Task Breakdown'!G79 -> Documentation, runbook and knowledge transfer | E15: ='Task Breakdown'!I79 -> 0 | F15: ='Task Breakdown'!J79 -> 0 | G15: ='Task Breakdown'!K79 -> 0 | H15: ='Task Breakdown'!L79 -> 0 | I15: ='Task Breakdown'!M79 -> 0 | J15: ='Task Breakdown'!N79 -> 5 | K15: ='Task Breakdown'!O79 -> 0 | L15: ='Task Breakdown'!P79 -> 0 | ... P15: ='Task Breakdown'!T79 -> 0 | Q15: =SUM(E15:P15) -> 5 | R15: =IF($Q$216>0,Q15/$Q$216,0) -> 0.0007733952
A16: ='Task Breakdown'!A80 -> PS-2.01.10 | B16: ='Task Breakdown'!G80 -> Defect fixing and rework after testing | E16: ='Task Breakdown'!I80 -> 0 | F16: ='Task Breakdown'!J80 -> 0 | G16: ='Task Breakdown'!K80 -> 0 | H16: ='Task Breakdown'!L80 -> 0 | I16: ='Task Breakdown'!M80 -> 0 | J16: ='Task Breakdown'!N80 -> 11 | K16: ='Task Breakdown'!O80 -> 0 | L16: ='Task Breakdown'!P80 -> 0 | ... P16: ='Task Breakdown'!T80 -> 0 | Q16: =SUM(E16:P16) -> 11 | R16: =IF($Q$216>0,Q16/$Q$216,0) -> 0.0017014695
A17: PS-2.02 | B17: AI gateway / model router: Azure OpenAI, Anthropic, Gemini, self-hosted | C17: Foundry | D17: Model router with quotas and fallbacks | E17: =SUM(E18:E29) -> 0 | F17: =SUM(F18:F29) -> 0 | G17: =SUM(G18:G29) -> 86 | H17: =SUM(H18:H29) -> 24 | I17: =SUM(I18:I29) -> 68 | J17: =SUM(J18:J29) -> 160 | K17: =SUM(K18:K29) -> 0 | L17: =SUM(L18:L29) -> 0 | ... Q17: =SUM(Q18:Q29) -> 387 | R17: =IF($Q$216>0,Q17/$Q$216,0) -> 0.059860789
A18: ='Task Breakdown'!A81 -> PS-2.02.01 | B18: ='Task Breakdown'!G81 -> Define model routing policy (task type, cost, latency, fallback) | E18: ='Task Breakdown'!I81 -> 0 | F18: ='Task Breakdown'!J81 -> 0 | G18: ='Task Breakdown'!K81 -> 0 | H18: ='Task Breakdown'!L81 -> 0 | I18: ='Task Breakdown'!M81 -> 31 | J18: ='Task Breakdown'!N81 -> 0 | K18: ='Task Breakdown'!O81 -> 0 | L18: ='Task Breakdown'!P81 -> 0 | ... P18: ='Task Breakdown'!T81 -> 0 | Q18: =SUM(E18:P18) -> 31 | R18: =IF($Q$216>0,Q18/$Q$216,0) -> 0.0047950503
A19: ='Task Breakdown'!A82 -> PS-2.02.02 | B19: ='Task Breakdown'!G82 -> Configure APIM AI gateway backends: Azure OpenAI, Anthropic, Gemini, self-hosted | E19: ='Task Breakdown'!I82 -> 0 | F19: ='Task Breakdown'!J82 -> 0 | G19: ='Task Breakdown'!K82 -> 43 | H19: ='Task Breakdown'!L82 -> 0 | I19: ='Task Breakdown'!M82 -> 0 | J19: ='Task Breakdown'!N82 -> 18 | K19: ='Task Breakdown'!O82 -> 0 | L19: ='Task Breakdown'!P82 -> 0 | ... P19: ='Task Breakdown'!T82 -> 0 | Q19: =SUM(E19:P19) -> 61 | R19: =IF($Q$216>0,Q19/$Q$216,0) -> 0.0094354215
A20: ='Task Breakdown'!A83 -> PS-2.02.03 | B20: ='Task Breakdown'!G83 -> Implement token-based rate limits and quotas per team and agent | E20: ='Task Breakdown'!I83 -> 0 | F20: ='Task Breakdown'!J83 -> 0 | G20: ='Task Breakdown'!K83 -> 18 | H20: ='Task Breakdown'!L83 -> 0 | I20: ='Task Breakdown'!M83 -> 0 | J20: ='Task Breakdown'!N83 -> 18 | K20: ='Task Breakdown'!O83 -> 0 | L20: ='Task Breakdown'!P83 -> 0 | ... P20: ='Task Breakdown'!T83 -> 0 | Q20: =SUM(E20:P20) -> 36 | R20: =IF($Q$216>0,Q20/$Q$216,0) -> 0.0055684455
A21: ='Task Breakdown'!A84 -> PS-2.02.04 | B21: ='Task Breakdown'!G84 -> Implement retry and fallback across regions and models | E21: ='Task Breakdown'!I84 -> 0 | F21: ='Task Breakdown'!J84 -> 0 | G21: ='Task Breakdown'!K84 -> 0 | H21: ='Task Breakdown'!L84 -> 0 | I21: ='Task Breakdown'!M84 -> 6 | J21: ='Task Breakdown'!N84 -> 37 | K21: ='Task Breakdown'!O84 -> 0 | L21: ='Task Breakdown'!P84 -> 0 | ... P21: ='Task Breakdown'!T84 -> 0 | Q21: =SUM(E21:P21) -> 43 | R21: =IF($Q$216>0,Q21/$Q$216,0) -> 0.0066511988
A22: ='Task Breakdown'!A85 -> PS-2.02.05 | B22: ='Task Breakdown'!G85 -> Deploy self-hosted model (vLLM on AKS) behind the gateway | E22: ='Task Breakdown'!I85 -> 0 | F22: ='Task Breakdown'!J85 -> 0 | G22: ='Task Breakdown'!K85 -> 12 | H22: ='Task Breakdown'!L85 -> 0 | I22: ='Task Breakdown'!M85 -> 0 | J22: ='Task Breakdown'!N85 -> 37 | K22: ='Task Breakdown'!O85 -> 0 | L22: ='Task Breakdown'!P85 -> 0 | ... P22: ='Task Breakdown'!T85 -> 0 | Q22: =SUM(E22:P22) -> 49 | R22: =IF($Q$216>0,Q22/$Q$216,0) -> 0.007579273
A23: ='Task Breakdown'!A86 -> PS-2.02.06 | B23: ='Task Breakdown'!G86 -> Emit token metrics and log prompts / responses securely | E23: ='Task Breakdown'!I86 -> 0 | F23: ='Task Breakdown'!J86 -> 0 | G23: ='Task Breakdown'!K86 -> 0 | H23: ='Task Breakdown'!L86 -> 12 | I23: ='Task Breakdown'!M86 -> 0 | J23: ='Task Breakdown'!N86 -> 12 | K23: ='Task Breakdown'!O86 -> 0 | L23: ='Task Breakdown'!P86 -> 0 | ... P23: ='Task Breakdown'!T86 -> 0 | Q23: =SUM(E23:P23) -> 24 | R23: =IF($Q$216>0,Q23/$Q$216,0) -> 0.003712297
A24: ='Task Breakdown'!A87 -> PS-2.02.07 | B24: ='Task Breakdown'!G87 -> Use managed identity for model access (no keys in apps) | E24: ='Task Breakdown'!I87 -> 0 | F24: ='Task Breakdown'!J87 -> 0 | G24: ='Task Breakdown'!K87 -> 0 | H24: ='Task Breakdown'!L87 -> 12 | I24: ='Task Breakdown'!M87 -> 12 | J24: ='Task Breakdown'!N87 -> 0 | K24: ='Task Breakdown'!O87 -> 0 | L24: ='Task Breakdown'!P87 -> 0 | ... P24: ='Task Breakdown'!T87 -> 0 | Q24: =SUM(E24:P24) -> 24 | R24: =IF($Q$216>0,Q24/$Q$216,0) -> 0.003712297
A25: ='Task Breakdown'!A88 -> PS-2.02.08 | B25: ='Task Breakdown'!G88 -> Load and failover testing | E25: ='Task Breakdown'!I88 -> 0 | F25: ='Task Breakdown'!J88 -> 0 | G25: ='Task Breakdown'!K88 -> 0 | H25: ='Task Breakdown'!L88 -> 0 | I25: ='Task Breakdown'!M88 -> 0 | J25: ='Task Breakdown'!N88 -> 0 | K25: ='Task Breakdown'!O88 -> 0 | L25: ='Task Breakdown'!P88 -> 0 | ... P25: ='Task Breakdown'!T88 -> 0 | Q25: =SUM(E25:P25) -> 49 | R25: =IF($Q$216>0,Q25/$Q$216,0) -> 0.007579273
A26: ='Task Breakdown'!A89 -> PS-2.02.09 | B26: ='Task Breakdown'!G89 -> Detailed design and design review | E26: ='Task Breakdown'!I89 -> 0 | F26: ='Task Breakdown'!J89 -> 0 | G26: ='Task Breakdown'!K89 -> 0 | H26: ='Task Breakdown'!L89 -> 0 | I26: ='Task Breakdown'!M89 -> 19 | J26: ='Task Breakdown'!N89 -> 0 | K26: ='Task Breakdown'!O89 -> 0 | L26: ='Task Breakdown'!P89 -> 0 | ... P26: ='Task Breakdown'!T89 -> 0 | Q26: =SUM(E26:P26) -> 19 | R26: =IF($Q$216>0,Q26/$Q$216,0) -> 0.0029389018
A27: ='Task Breakdown'!A90 -> PS-2.02.10 | B27: ='Task Breakdown'!G90 -> Promote through dev / test / prod and release | E27: ='Task Breakdown'!I90 -> 0 | F27: ='Task Breakdown'!J90 -> 0 | G27: ='Task Breakdown'!K90 -> 13 | H27: ='Task Breakdown'!L90 -> 0 | I27: ='Task Breakdown'!M90 -> 0 | J27: ='Task Breakdown'!N90 -> 0 | K27: ='Task Breakdown'!O90 -> 0 | L27: ='Task Breakdown'!P90 -> 0 | ... P27: ='Task Breakdown'!T90 -> 0 | Q27: =SUM(E27:P27) -> 13 | R27: =IF($Q$216>0,Q27/$Q$216,0) -> 0.0020108275
A28: ='Task Breakdown'!A91 -> PS-2.02.11 | B28: ='Task Breakdown'!G91 -> Documentation, runbook and knowledge transfer | E28: ='Task Breakdown'!I91 -> 0 | F28: ='Task Breakdown'!J91 -> 0 | G28: ='Task Breakdown'!K91 -> 0 | H28: ='Task Breakdown'!L91 -> 0 | I28: ='Task Breakdown'!M91 -> 0 | J28: ='Task Breakdown'!N91 -> 13 | K28: ='Task Breakdown'!O91 -> 0 | L28: ='Task Breakdown'!P91 -> 0 | ... P28: ='Task Breakdown'!T91 -> 0 | Q28: =SUM(E28:P28) -> 13 | R28: =IF($Q$216>0,Q28/$Q$216,0) -> 0.0020108275
A29: ='Task Breakdown'!A92 -> PS-2.02.12 | B29: ='Task Breakdown'!G92 -> Defect fixing and rework after testing | E29: ='Task Breakdown'!I92 -> 0 | F29: ='Task Breakdown'!J92 -> 0 | G29: ='Task Breakdown'!K92 -> 0 | H29: ='Task Breakdown'!L92 -> 0 | I29: ='Task Breakdown'!M92 -> 0 | J29: ='Task Breakdown'!N92 -> 25 | K29: ='Task Breakdown'!O92 -> 0 | L29: ='Task Breakdown'!P92 -> 0 | ... P29: ='Task Breakdown'!T92 -> 0 | Q29: =SUM(E29:P29) -> 25 | R29: =IF($Q$216>0,Q29/$Q$216,0) -> 0.003866976
A30: PS-2.03 | B30: Agent orchestrator: Foundry Agent Service, Semantic Kernel, LangGraph | C30: Foundry | D30: Orchestration framework and reference agent | E30: =SUM(E31:E42) -> 0 | F30: =SUM(F31:F42) -> 0 | G30: =SUM(G31:G42) -> 22 | H30: =SUM(H31:H42) -> 0 | I30: =SUM(I31:I42) -> 130 | J30: =SUM(J31:J42) -> 358 | K30: =SUM(K31:K42) -> 0 | L30: =SUM(L31:L42) -> 0 | ... Q30: =SUM(Q31:Q42) -> 657 | R30: =IF($Q$216>0,Q30/$Q$216,0) -> 0.10162413
A31: ='Task Breakdown'!A93 -> PS-2.03.01 | B31: ='Task Breakdown'!G93 -> Evaluate and select orchestration options (Foundry Agent Service, Semantic Kernel, LangGraph) | E31: ='Task Breakdown'!I93 -> 0 | F31: ='Task Breakdown'!J93 -> 0 | G31: ='Task Breakdown'!K93 -> 0 | H31: ='Task Breakdown'!L93 -> 0 | I31: ='Task Breakdown'!M93 -> 37 | J31: ='Task Breakdown'!N93 -> 25 | K31: ='Task Breakdown'!O93 -> 0 | L31: ='Task Breakdown'!P93 -> 0 | ... P31: ='Task Breakdown'!T93 -> 0 | Q31: =SUM(E31:P31) -> 62 | R31: =IF($Q$216>0,Q31/$Q$216,0) -> 0.0095901005
A32: ='Task Breakdown'!A94 -> PS-2.03.02 | B32: ='Task Breakdown'!G94 -> Define agent design standards: tools, state, guardrails, handoff | E32: ='Task Breakdown'!I94 -> 0 | F32: ='Task Breakdown'!J94 -> 0 | G32: ='Task Breakdown'!K94 -> 0 | H32: ='Task Breakdown'!L94 -> 0 | I32: ='Task Breakdown'!M94 -> 31 | J32: ='Task Breakdown'!N94 -> 0 | K32: ='Task Breakdown'!O94 -> 0 | L32: ='Task Breakdown'!P94 -> 0 | ... P32: ='Task Breakdown'!T94 -> 0 | Q32: =SUM(E32:P32) -> 31 | R32: =IF($Q$216>0,Q32/$Q$216,0) -> 0.0047950503
A33: ='Task Breakdown'!A95 -> PS-2.03.03 | B33: ='Task Breakdown'!G95 -> Build orchestration service skeleton (API, sessions, state store) | E33: ='Task Breakdown'!I95 -> 0 | F33: ='Task Breakdown'!J95 -> 0 | G33: ='Task Breakdown'!K95 -> 0 | H33: ='Task Breakdown'!L95 -> 0 | I33: ='Task Breakdown'!M95 -> 0 | J33: ='Task Breakdown'!N95 -> 73 | K33: ='Task Breakdown'!O95 -> 0 | L33: ='Task Breakdown'!P95 -> 0 | ... P33: ='Task Breakdown'!T95 -> 0 | Q33: =SUM(E33:P33) -> 110 | R33: =IF($Q$216>0,Q33/$Q$216,0) -> 0.017014695
A34: ='Task Breakdown'!A96 -> PS-2.03.04 | B34: ='Task Breakdown'!G96 -> Implement tool calling and agent-to-agent handoff | E34: ='Task Breakdown'!I96 -> 0 | F34: ='Task Breakdown'!J96 -> 0 | G34: ='Task Breakdown'!K96 -> 0 | H34: ='Task Breakdown'!L96 -> 0 | I34: ='Task Breakdown'!M96 -> 0 | J34: ='Task Breakdown'!N96 -> 73 | K34: ='Task Breakdown'!O96 -> 0 | L34: ='Task Breakdown'!P96 -> 0 | ... P34: ='Task Breakdown'!T96 -> 0 | Q34: =SUM(E34:P34) -> 73 | R34: =IF($Q$216>0,Q34/$Q$216,0) -> 0.01129157
